<?xml version="1.0" encoding="utf-8"?>
<robot name="dofbot">
    <link name="base_link">
        <visual>
            <origin
                    xyz="0 0 0"
                    rpy="0 0 0"/>
            <geometry>
                <mesh
                        filename="package://dofbot_moveit/meshes/base_link.STL"/>
            </geometry>
            <material
                    name="">
                <color
                        rgba="0.7 0.7 0.7 1"/>
            </material>
        </visual>
        <collision>
            <origin
                    xyz="0 0 0"
                    rpy="0 0 0"/>
            <geometry>
                <mesh
                        filename="package://dofbot_moveit/meshes/base_link.STL"/>
            </geometry>
        </collision>
    </link>
    <link name="link1">
        <visual>
            <origin
                    xyz="0 0 0"
                    rpy="0 0 0"/>
            <geometry>
                <mesh
                        filename="package://dofbot_moveit/meshes/link1.STL"/>
            </geometry>
            <material
                    name="">
                <color
                        rgba="0 0.7 0 1"/>
            </material>
        </visual>
        <collision>
            <origin
                    xyz="0 0 0"
                    rpy="0 0 0"/>
            <geometry>
                <mesh
                        filename="package://dofbot_moveit/meshes/link1.STL"/>
            </geometry>
        </collision>
    </link>
    <joint name="joint1" type="revolute">
        <origin
                xyz="0 0 0.064"
                rpy="0 0 0"/>
        <parent
                link="base_link"/>
        <child
                link="link1"/>
        <axis
                xyz="0 0 1"/>
        <limit
                lower="-1.5708"
                upper="1.5708"
                effort="100"
                velocity="1"/>
    </joint>
    <link name="link2">
        <visual>
            <origin
                    xyz="0 0 0"
                    rpy="0 0 0"/>
            <geometry>
                <mesh
                        filename="package://dofbot_moveit/meshes/link2.STL"/>
            </geometry>
            <material
                    name="">
                <color
                        rgba="0.7 0.7 0.7 1"/>
            </material>
        </visual>
        <collision>
            <origin
                    xyz="0 0 0"
                    rpy="0 0 0"/>
            <geometry>
                <mesh
                        filename="package://dofbot_moveit/meshes/link2.STL"/>
            </geometry>
        </collision>
    </link>
    <joint name="joint2" type="revolute">
        <origin
                xyz="0 0 0.0435"
                rpy="0 1.5708 0"/>
        <parent
                link="link1"/>
        <child
                link="link2"/>
        <axis
                xyz="0 0 1"/>
        <limit
                lower="-1.5708"
                upper="1.5708"
                effort="100"
                velocity="1"/>
    </joint>
    <link name="link3">
        <visual>
            <origin
                    xyz="0 0 0"
                    rpy="0 0 0"/>
            <geometry>
                <mesh
                        filename="package://dofbot_moveit/meshes/link3.STL"/>
            </geometry>
            <material
                    name="">
                <color
                        rgba="0 0.7 0 1"/>
            </material>
        </visual>
        <collision>
            <origin
                    xyz="0 0 0"
                    rpy="0 0 0"/>
            <geometry>
                <mesh
                        filename="package://dofbot_moveit/meshes/link3.STL"/>
            </geometry>
        </collision>
    </link>
    <joint name="joint3" type="revolute">
        <origin
                xyz="-0.08285 0 0"
                rpy="0 0 0"/>
        <parent
                link="link2"/>
        <child
                link="link3"/>
        <axis
                xyz="0 0 1"/>
        <limit
                lower="-1.5708"
                upper="1.5708"
                effort="100"
                velocity="1"/>
    </joint>
    <link name="link4">
        <visual>
            <origin
                    xyz="0 0 0"
                    rpy="0 0 0"/>
            <geometry>
                <mesh
                        filename="package://dofbot_moveit/meshes/link4.STL"/>
            </geometry>
            <material
                    name="">
                <color
                        rgba="0.7 0.7 0.7 1"/>
            </material>
        </visual>
        <collision>
            <origin
                    xyz="0 0 0"
                    rpy="0 0 0"/>
            <geometry>
                <mesh
                        filename="package://dofbot_moveit/meshes/link4.STL"/>
            </geometry>
        </collision>
    </link>
    <joint name="joint4" type="revolute">
        <origin
                xyz="-0.08285 0 0"
                rpy="0 0 0"/>
        <parent
                link="link3"/>
        <child
                link="link4"/>
        <axis
                xyz="0 0 1"/>
        <limit
                lower="-1.5708"
                upper="1.5708"
                effort="100"
                velocity="1"/>
    </joint>
    <link name="link5">
        <visual>
            <origin
                    xyz="0 0 0"
                    rpy="0 0 0"/>
            <geometry>
                <mesh
                        filename="package://dofbot_moveit/meshes/link5.STL"/>
            </geometry>
            <material
                    name="">
                <color
                        rgba="1 1 1 1"/>
            </material>
        </visual>
        <collision>
            <origin
                    xyz="0 0 0"
                    rpy="0 0 0"/>
            <geometry>
                <mesh
                        filename="package://dofbot_moveit/meshes/link5.STL"/>
            </geometry>
        </collision>
    </link>
    <joint name="joint5" type="revolute">
        <origin
                xyz="-0.07385 -0.00215 0"
                rpy="0 -1.5708 0"/>
        <parent
                link="link4"/>
        <child
                link="link5"/>
        <axis
                xyz="0 0 1"/>
        <limit
                lower="-1.5708"
                upper="3.1416"
                effort="100"
                velocity="1"/>
    </joint>
</robot>